#from pymongo.errors import PyMongoError
#
#from tests.mongo_migration.test_test_app_get_books_test_get_books_sqlalchemy_error_handled import *
#from unittest.mock import Mock, patch
#
#
#from unittest.mock import Mock, patch
#
#import pytest
#
#
## A fixture to mock pymongo collection
#@pytest.fixture
#def mock_pymongo_collection():
#    mock_collection = Mock(name="Mock PyMongo Collection")
#    return mock_collection
#
#
#def test_get_books_pymongo_executes_without_errors(mock_pymongo_collection):
#    mock_pymongo_collection.find.return_value = []
#
#    # Assuming the existence of the `get_books` function which now uses PyMongo
#    try:
#        # Call the function with the mocked pymongo collection
#        result = get_books(mock_pymongo_collection)
#        assert result is not None
#    except Exception as e:
#        pytest.fail(f"An error occurred: {str(e)}")
#
#
#def test_get_books_pymongo_error_handled(mock_pymongo_collection):
#    # Mimic PyMongoError exception when accessing the collection
#    mock_pymongo_collection.find.side_effect = PyMongoError
#
#    with patch("builtins.print") as mock_print:
#        # Assuming the existence of the `get_books` function which now uses PyMongo
#        books = get_books(mock_pymongo_collection)
#        assert mock_print.call_count == 1
#        mock_pymongo_collection.find.assert_called_once()
#        assert books == []
#
## Imports
#from pytest import fixture
#